<?xml version="1.0"?>
<robot name="my_robot" xmlns:xacro="http://www.ros.org/wiki/xacro">

  <material name="light_blue"><color rgba="0.792 0.819 0.933 1" /></material>
  <material name="gray"><color rgba="0.752 0.752 0.752 1" /></material>
  <material name="black"><color rgba="0.1 0.1 0.1 1" /></material>
  <material name="red"><color rgba="1.0 0.0 0.0 1.0" /></material>

  <xacro:property name="dist_center" value="0.10777" />
  <xacro:property name="wheel_z_offset" value="-0.01" />
  <xacro:property name="PI" value="3.1415926535897931" />

  <xacro:macro name="omni_wheel" params="prefix x y yaw">
    <link name="wheel_${prefix}_link">
      <inertial>
        <origin xyz="2.06E-06 -1.37E-06 -0.00012" rpy="0 0 0" />
        <mass value="0.03769" />
        <inertia ixx="3.09E-06" ixy="0" ixz="0" iyy="3.09E-06" iyz="0" izz="5.34E-06" />
      </inertial>
      <visual>
        <origin xyz="0 0 0" rpy="0 0 0" />
        <geometry><mesh filename="package://my_robot_description/meshes/wheel_1.STL" /></geometry>
        <material name="gray" />
      </visual>
      <collision>
        <origin xyz="0 0 0" rpy="0 0 0" />
        <geometry><mesh filename="package://my_robot_description/meshes/wheel_1.STL" /></geometry>
      </collision>
    </link>
    <joint name="w${prefix}_joint" type="continuous">
      <parent link="base_link" />
      <child link="wheel_${prefix}_link" />
      <origin xyz="${x} ${y} ${wheel_z_offset}" rpy="${PI/2} 0 ${yaw}" />
      <axis xyz="0 0 1" />
    </joint>
  </xacro:macro>

  <link name="base_footprint"/>
  <joint name="base_joint" type="fixed">
    <parent link="base_footprint"/>
    <child link="base_link"/>
    <origin xyz="0 0 0.05" rpy="0 0 0"/>
  </joint>

  <link name="base_link">
    <inertial>
      <origin xyz="8.12E-10 0.00063 -0.00024" rpy="0 0 0" />
      <mass value="1.603" />
      <inertia ixx="0.00524" ixy="0" ixz="0" iyy="0.00524" iyz="0" izz="0.00982" />
    </inertial>
    <visual>
      <geometry><mesh filename="package://my_robot_description/meshes/base_link.STL" /></geometry>
      <material name="light_blue" />
    </visual>
    <collision>
      <geometry><mesh filename="package://my_robot_description/meshes/base_link.STL" /></geometry>
    </collision>
  </link>

  <xacro:omni_wheel prefix="1" x="0" y="-${dist_center}" yaw="0" />
  <xacro:omni_wheel prefix="2" x="${dist_center * cos(PI/6)}" y="${dist_center * sin(PI/6)}" yaw="${2*PI/3}" />
  <xacro:omni_wheel prefix="3" x="-${dist_center * cos(PI/6)}" y="${dist_center * sin(PI/6)}" yaw="-${2*PI/3}" />

  <link name="link_1">
    <inertial> 
      <origin xyz="6.59E-05 -1.48E-05 0.075" rpy="0 0 0" />
      <mass value="0.101" />
      <inertia ixx="0.00014" ixy="0" ixz="0" iyy="0.00014" iyz="0" izz="1.36E-05" />
    </inertial>
    <visual>
      <geometry><mesh filename="package://my_robot_description/meshes/link_1.STL" /></geometry>
      <material name="light_blue" />
    </visual>
    <collision>
      <geometry><mesh filename="package://my_robot_description/meshes/link_1.STL" /></geometry>
    </collision>
  </link>
  <joint name="l1" type="revolute">
    <origin xyz="0 0 0" rpy="0 0 0" />
    <parent link="base_link" />
    <child link="link_1" />
    <axis xyz="0 0 -1" />
    <limit lower="-3.14" upper="3.14" effort="50" velocity="2" />
    <dynamics damping="0.1" friction="0.0" />
  </joint>

  <link name="link_2">
    <inertial> 
      <origin xyz="0 0 0.101" rpy="0 0 0" />
      <mass value="0.096" />
      <inertia ixx="0.00023" ixy="0" ixz="0" iyy="0.00022" iyz="0" izz="1.59E-05" />
    </inertial>
    <visual>
      <geometry><mesh filename="package://my_robot_description/meshes/link_2.STL" /></geometry>
      <material name="light_blue" />
    </visual>
    <collision>
      <geometry><mesh filename="package://my_robot_description/meshes/link_2.STL" /></geometry>
    </collision>
  </link>
<joint name="l2" type="prismatic">
    <origin xyz="0 0 0.135" rpy="${PI/2} 0 -1.79" />
    <parent link="link_1" />
    <child link="link_2" />
    <axis xyz="0 0 -1" /> 
    <limit lower="-0.025" upper="0.025" effort="50" velocity="1" />
    <dynamics damping="0.1" friction="0.0" />
  </joint>

  <link name="imu_link"/>
  <joint name="imu_joint" type="fixed">
    <parent link="base_link"/>
    <child link="imu_link"/>
    <origin xyz="0 0 0" rpy="0 0 0"/>
  </joint>

  <gazebo reference="imu_link">
    <sensor name="imu_sensor" type="imu">
      <always_on>true</always_on>
      <update_rate>100</update_rate>
      <plugin name="imu_plugin" filename="libgazebo_ros_imu_sensor.so">
        <ros><remapping>~/out:=imu/data</remapping></ros>
        <initial_orientation_as_reference>false</initial_orientation_as_reference>
      </plugin>
    </sensor>
  </gazebo>

  <link name="lidar_link">
    <visual>
      <geometry><cylinder radius="0.03" length="0.04"/></geometry>
      <material name="black"/>
    </visual>
  </link>
  <joint name="lidar_joint" type="fixed">
    <parent link="base_link"/>
    <child link="lidar_link"/>
    <origin xyz="0.0 0.08 0.035" rpy="0 0 0"/>
  </joint>

  <gazebo reference="lidar_link">
    <material>Gazebo/Black</material>
    <sensor name="lidar" type="ray">
      <always_on>true</always_on>
      <visualize>true</visualize> <update_rate>10</update_rate>
      <ray>
        <scan>
          <horizontal>
            <samples>360</samples>
            <resolution>1</resolution>
            <min_angle>-3.14159</min_angle>
            <max_angle>3.14159</max_angle>
          </horizontal>
        </scan>
        <range>
          <min>0.15</min>
          <max>12.0</max>
          <resolution>0.015</resolution>
        </range>
      </ray>
      <plugin name="scan" filename="libgazebo_ros_ray_sensor.so">
        <ros><remapping>~/out:=scan</remapping></ros>
        <output_type>sensor_msgs/LaserScan</output_type>
        <frame_name>lidar_link</frame_name>
      </plugin>
    </sensor>
  </gazebo>

  <link name="camera_link">
    <visual>
      <geometry><box size="0.02 0.05 0.03"/></geometry>
      <material name="red"/>
    </visual>
  </link>
  
  <joint name="camera_joint" type="fixed">
    <parent link="base_link"/>
    <child link="camera_link"/>
    <origin xyz="0.0 0.1 0.0" rpy="0 0 ${PI/2}"/>
  </joint>

  <gazebo reference="camera_link">
    <material>Gazebo/Black</material>
    <sensor type="camera" name="camera_sensor">
      <update_rate>30.0</update_rate>
      <camera name="head">
        <horizontal_fov>1.3962634</horizontal_fov>
        <image>
          <width>800</width>
          <height>800</height>
          <format>R8G8B8</format>
        </image>
        <clip>
          <near>0.02</near>
          <far>300</far>
        </clip>
      </camera>
      <plugin name="camera_controller" filename="libgazebo_ros_camera.so">
        <alwaysOn>true</alwaysOn>
        <updateRate>0.0</updateRate>
        <cameraName>camera</cameraName>
        <imageTopicName>image_raw</imageTopicName>
        <cameraInfoTopicName>camera_info</cameraInfoTopicName>
        <frameName>camera_link</frameName>
      </plugin>
    </sensor>
  </gazebo>

  <gazebo>
    <plugin name="omni_steering" filename="libgazebo_ros_planar_move.so">
      <ros>
        <remapping>cmd_vel:=cmd_vel</remapping>
        <remapping>odom:=odom</remapping>
      </ros>
      <update_rate>50.0</update_rate>
      <publish_rate>50.0</publish_rate>
      
      <publish_odom>true</publish_odom>
      <publish_odom_tf>true</publish_odom_tf>
      
      <odometry_frame>odom</odometry_frame>
      <robot_base_frame>base_footprint</robot_base_frame>
      
      <covariance_x>0.0001</covariance_x>
      <covariance_y>0.0001</covariance_y>
      <covariance_yaw>0.0001</covariance_yaw>
    </plugin>
  </gazebo>
<ros2_control name="GazeboSystem" type="system">
    <hardware>
      <plugin>gazebo_ros2_control/GazeboSystem</plugin>
    </hardware>
    
    <joint name="l1">
      <command_interface name="position"/>
      <state_interface name="position"/>
      <state_interface name="velocity"/>
    </joint>
    
    <joint name="l2">
      <command_interface name="position"/>
      <state_interface name="position"/>
      <state_interface name="velocity"/>
    </joint>
  </ros2_control>
!-- Transmissions for ROS 2 Control -->
  <transmission name="l1_transmission">
    <type>transmission_interface/SimpleTransmission</type>
    <joint name="l1">
      <hardwareInterface>hardware_interface/PositionCommandInterface</hardwareInterface>
    </joint>
    <actuator name="l1_motor">
      <hardwareInterface>hardware_interface/PositionCommandInterface</hardwareInterface>
      <mechanicalReduction>1</mechanicalReduction>
    </actuator>
  </transmission>

  <transmission name="l2_transmission">
    <type>transmission_interface/SimpleTransmission</type>
    <joint name="l2">
      <hardwareInterface>hardware_interface/PositionCommandInterface</hardwareInterface>
    </joint>
    <actuator name="l2_motor">
      <hardwareInterface>hardware_interface/PositionCommandInterface</hardwareInterface>
      <mechanicalReduction>1</mechanicalReduction>
    </actuator>
  </transmission>

  <gazebo>
    <plugin name="gazebo_ros2_control" filename="libgazebo_ros2_control.so">
      <parameters>$(find my_robot_description)/config/controllers.yaml</parameters>
    </plugin>
  </gazebo>
</robot>